Workbook
Name Slicer_Category: #N/A
Name Slicer_Region: #N/A
Name Slicer_Salesperson: #N/A

Sheet clean_data
A1: Order ID | B1: Order Date | C1: Customer | D1: Region | E1: Salesperson | F1: Category | G1: Product | H1: Quantity | I1: Unit Price | J1: Discount % | K1: Sales | L1: Discount Amount | M1: Duplicate Id Check
A2: ORD10001 | B2: 46058 | C2: Ritu Sharma | D2: East | E2: Rahul | F2: Furniture | G2: Cabinet | H2: 14 | I2: 41963 | J2: 20 | K2: 469985.6 | L2: =Raw_Sales_Data3[[#This Row],[Quantity]]*Raw_Sales_Data3[[#This Row],[Unit Price]]*(Raw_Sales_Data3[[#This Row],[Discount %]]/100) -> 117496.4 | M2: =IF(COUNTIF(Raw_Sales_Data3[Order ID],Raw_Sales_Data3[[#This Row],[Order ID]])>1,"Duplicate Order ID","Unique Order ID") -> Unique Order ID
A3: ORD10002 | B3: 46039 | C3: Amit Sharma | D3: South | E3: Rohit | F3: Electronics | G3: Headphones | H3: 3 | I3: 9724 | J3: 0 | K3: 29172 | L3: =Raw_Sales_Data3[[#This Row],[Quantity]]*Raw_Sales_Data3[[#This Row],[Unit Price]]*(Raw_Sales_Data3[[#This Row],[Discount %]]/100) -> 0 | M3: =IF(COUNTIF(Raw_Sales_Data3[Order ID],Raw_Sales_Data3[[#This Row],[Order ID]])>1,"Duplicate Order ID","Unique Order ID") -> Unique Order ID
A4: ORD10003 | B4: 46076 | C4: Pooja Mehta | D4: South | E4: Rohit | F4: Office Supplies | G4: File Cabinet | H4: 4 | I4: 48847 | J4: 20 | K4: 156310.4 | L4: =Raw_Sales_Data3[[#This Row],[Quantity]]*Raw_Sales_Data3[[#This Row],[Unit Price]]*(Raw_Sales_Data3[[#This Row],[Discount %]]/100) -> 39077.6 | M4: =IF(COUNTIF(Raw_Sales_Data3[Order ID],Raw_Sales_Data3[[#This Row],[Order ID]])>1,"Duplicate Order ID","Unique Order ID") -> Unique Order ID
A5: ORD10004 | B5: 46100 | C5: Nisha Jain | D5: West | E5: Kiran | F5: Office Supplies | G5: Projector | H5: 5 | I5: 21900 | J5: 20 | K5: 87600 | L5: =Raw_Sales_Data3[[#This Row],[Quantity]]*Raw_Sales_Data3[[#This Row],[Unit Price]]*(Raw_Sales_Data3[[#This Row],[Discount %]]/100) -> 21900 | M5: =IF(COUNTIF(Raw_Sales_Data3[Order ID],Raw_Sales_Data3[[#This Row],[Order ID]])>1,"Duplicate Order ID","Unique Order ID") -> Unique Order ID
A6: ORD10005 | B6: 46027 | C6: Meera Nair | D6: South | E6: Rohit | F6: Electronics | G6: Speaker | H6: 10 | I6: 43412 | J6: 10 | K6: 390708 | L6: =Raw_Sales_Data3[[#This Row],[Quantity]]*Raw_Sales_Data3[[#This Row],[Unit Price]]*(Raw_Sales_Data3[[#This Row],[Discount %]]/100) -> 43412 | M6: =IF(COUNTIF(Raw_Sales_Data3[Order ID],Raw_Sales_Data3[[#This Row],[Order ID]])>1,"Duplicate Order ID","Unique Order ID") -> Unique Order ID
A7: ORD10006 | B7: 46045 | C7: Rohan Singh | D7: North | E7: Sneha | F7: Office Supplies | G7: Projector | H7: 4 | I7: 8907 | J7: 15 | K7: 30283.8 | L7: =Raw_Sales_Data3[[#This Row],[Quantity]]*Raw_Sales_Data3[[#This Row],[Unit Price]]*(Raw_Sales_Data3[[#This Row],[Discount %]]/100) -> 5344.2 | M7: =IF(COUNTIF(Raw_Sales_Data3[Order ID],Raw_Sales_Data3[[#This Row],[Order ID]])>1,"Duplicate Order ID","Unique Order ID") -> Unique Order ID
A8: ORD10007 | B8: 46039 | C8: Aditya Joshi | D8: West | E8: Rohit | F8: Office Supplies | G8: Projector | H8: 6 | I8: 10421 | J8: 0 | K8: 62526 | L8: =Raw_Sales_Data3[[#This Row],[Quantity]]*Raw_Sales_Data3[[#This Row],[Unit Price]]*(Raw_Sales_Data3[[#This Row],[Discount %]]/100) -> 0 | M8: =IF(COUNTIF(Raw_Sales_Data3[Order ID],Raw_Sales_Data3[[#This Row],[Order ID]])>1,"Duplicate Order ID","Unique Order ID") -> Unique Order ID
A9: ORD10008 | B9: 46028 | C9: Priya Patel | D9: North | E9: Ajay | F9: Office Supplies | G9: Camera | H9: 11 | I9: 35012 | J9: 5 | K9: 365875.4 | L9: =Raw_Sales_Data3[[#This Row],[Quantity]]*Raw_Sales_Data3[[#This Row],[Unit Price]]*(Raw_Sales_Data3[[#This Row],[Discount %]]/100) -> 19256.6 | M9: =IF(COUNTIF(Raw_Sales_Data3[Order ID],Raw_Sales_Data3[[#This Row],[Order ID]])>1,"Duplicate Order ID","Unique Order ID") -> Unique Order ID
A10: ORD10009 | B10: 46039 | C10: Mohit Kumar | D10: East | E10: Sneha | F10: Electronics | G10: Monitor | H10: 3 | I10: 32854 | J10: 0 | K10: 98562 | L10: =Raw_Sales_Data3[[#This Row],[Quantity]]*Raw_Sales_Data3[[#This Row],[Unit Price]]*(Raw_Sales_Data3[[#This Row],[Discount %]]/100) -> 0 | M10: =IF(COUNTIF(Raw_Sales_Data3[Order ID],Raw_Sales_Data3[[#This Row],[Order ID]])>1,"Duplicate Order ID","Unique Order ID") -> Unique Order ID
A11: ORD10010 | B11: 46112 | C11: Harsh Patel | D11: South | E11: Rohit | F11: Electronics | G11: Tablet | H11: 8 | I11: 27803 | J11: 0 | K11: 222424 | L11: =Raw_Sales_Data3[[#This Row],[Quantity]]*Raw_Sales_Data3[[#This Row],[Unit Price]]*(Raw_Sales_Data3[[#This Row],[Discount %]]/100) -> 0 | M11: =IF(COUNTIF(Raw_Sales_Data3[Order ID],Raw_Sales_Data3[[#This Row],[Order ID]])>1,"Duplicate Order ID","Unique Order ID") -> Unique Order ID
A12: ORD10011 | B12: 46089 | C12: Ravi Kumar | D12: South | E12: Rohit | F12: Office Supplies | G12: Projector | H12: 14 | I12: 15767 | J12: 20 | K12: 176590.4 | L12: =Raw_Sales_Data3[[#This Row],[Quantity]]*Raw_Sales_Data3[[#This Row],[Unit Price]]*(Raw_Sales_Data3[[#This Row],[Discount %]]/100) -> 44147.6 | M12: =IF(COUNTIF(Raw_Sales_Data3[Order ID],Raw_Sales_Data3[[#This Row],[Order ID]])>1,"Duplicate Order ID","Unique Order ID") -> Unique Order ID
A13: ORD10012 | B13: 46041 | C13: Snehal Kulkarni | D13: South | E13: Sneha | F13: Furniture | G13: Chair | H13: 10 | I13: 20085 | J13: 0 | K13: 200850 | L13: =Raw_Sales_Data3[[#This Row],[Quantity]]*Raw_Sales_Data3[[#This Row],[Unit Price]]*(Raw_Sales_Data3[[#This Row],[Discount %]]/100) -> 0 | M13: =IF(COUNTIF(Raw_Sales_Data3[Order ID],Raw_Sales_Data3[[#This Row],[Order ID]])>1,"Duplicate Order ID","Unique Order ID") -> Unique Order ID
... A20: ORD10019 | B20: 46049 | C20: Ritu Sharma | D20: South | E20: Rahul | F20: Furniture | G20: Dining Table | H20: 6 | I20: 4943 | J20: 0 | K20: 29658 | L20: =Raw_Sales_Data3[[#This Row],[Quantity]]*Raw_Sales_Data3[[#This Row],[Unit Price]]*(Raw_Sales_Data3[[#This Row],[Discount %]]/100) -> 0 | M20: =IF(COUNTIF(Raw_Sales_Data3[Order ID],Raw_Sales_Data3[[#This Row],[Order ID]])>1,"Duplicate Order ID","Unique Order ID") -> Unique Order ID
A21: ORD10020 | B21: 46054 | C21: Snehal Kulkarni | D21: West | E21: Kiran | F21: Electronics | G21: Headphones | H21: 3 | I21: =K21/H21 -> 26972.4 | J21: 5 | K21: 80917.2 | L21: =Raw_Sales_Data3[[#This Row],[Quantity]]*Raw_Sales_Data3[[#This Row],[Unit Price]]*(Raw_Sales_Data3[[#This Row],[Discount %]]/100) -> 4045.86 | M21: =IF(COUNTIF(Raw_Sales_Data3[Order ID],Raw_Sales_Data3[[#This Row],[Order ID]])>1,"Duplicate Order ID","Unique Order ID") -> Unique Order ID
A22: ORD10021 | B22: 46105 | C22: Meera Nair | D22: North | E22: Kiran | F22: Office Supplies | G22: Printer | H22: 8 | I22: 36089 | J22: 10 | K22: 259840.8 | L22: =Raw_Sales_Data3[[#This Row],[Quantity]]*Raw_Sales_Data3[[#This Row],[Unit Price]]*(Raw_Sales_Data3[[#This Row],[Discount %]]/100) -> 28871.2 | M22: =IF(COUNTIF(Raw_Sales_Data3[Order ID],Raw_Sales_Data3[[#This Row],[Order ID]])>1,"Duplicate Order ID","Unique Order ID") -> Unique Order ID
A23: ORD10022 | B23: 46038 | C23: Pooja Mehta | D23: North | E23: Kiran | F23: Furniture | G23: Coffee Table | H23: 1 | I23: 39900 | J23: 0 | K23: 39900 | L23: =Raw_Sales_Data3[[#This Row],[Quantity]]*Raw_Sales_Data3[[#This Row],[Unit Price]]*(Raw_Sales_Data3[[#This Row],[Discount %]]/100) -> 0 | M23: =IF(COUNTIF(Raw_Sales_Data3[Order ID],Raw_Sales_Data3[[#This Row],[Order ID]])>1,"Duplicate Order ID","Unique Order ID") -> Unique Order ID
A24: ORD10023 | B24: 46066 | C24: Rohan Singh | D24: South | E24: Rohit | F24: Electronics | G24: Mouse | H24: 8 | I24: 54319 | J24: 0 | K24: 434552 | L24: =Raw_Sales_Data3[[#This Row],[Quantity]]*Raw_Sales_Data3[[#This Row],[Unit Price]]*(Raw_Sales_Data3[[#This Row],[Discount %]]/100) -> 0 | M24: =IF(COUNTIF(Raw_Sales_Data3[Order ID],Raw_Sales_Data3[[#This Row],[Order ID]])>1,"Duplicate Order ID","Unique Order ID") -> Unique Order ID
A25: ORD10024 | B25: 46031 | C25: Mohit Kumar | D25: South | E25: Rahul | F25: Electronics | G25: Tablet | H25: 14 | I25: 54969 | J25: 0 | K25: 769566 | L25: =Raw_Sales_Data3[[#This Row],[Quantity]]*Raw_Sales_Data3[[#This Row],[Unit Price]]*(Raw_Sales_Data3[[#This Row],[Discount %]]/100) -> 0 | M25: =IF(COUNTIF(Raw_Sales_Data3[Order ID],Raw_Sales_Data3[[#This Row],[Order ID]])>1,"Duplicate Order ID","Unique Order ID") -> Unique Order ID
A26: ORD10025 | B26: 46027 | C26: Komal Gupta | D26: East | E26: Rahul | F26: Office Supplies | G26: Whiteboard | H26: 2 | I26: 10426 | J26: 15 | K26: 17724.2 | L26: =Raw_Sales_Data3[[#This Row],[Quantity]]*Raw_Sales_Data3[[#This Row],[Unit Price]]*(Raw_Sales_Data3[[#This Row],[Discount %]]/100) -> 3127.8 | M26: =IF(COUNTIF(Raw_Sales_Data3[Order ID],Raw_Sales_Data3[[#This Row],[Order ID]])>1,"Duplicate Order ID","Unique Order ID") -> Unique Order ID
A27: ORD10026 | B27: 46101 | C27: Nisha Jain | D27: South | E27: Sneha | F27: Electronics | G27: Laptop | H27: 14 | I27: 25305 | J27: 0 | K27: 354270 | L27: =Raw_Sales_Data3[[#This Row],[Quantity]]*Raw_Sales_Data3[[#This Row],[Unit Price]]*(Raw_Sales_Data3[[#This Row],[Discount %]]/100) -> 0 | M27: =IF(COUNTIF(Raw_Sales_Data3[Order ID],Raw_Sales_Data3[[#This Row],[Order ID]])>1,"Duplicate Order ID","Unique Order ID") -> Unique Order ID
A28: ORD10027 | B28: 46067 | C28: Priya Patel | D28: West | E28: Rohit | F28: Electronics | G28: Headphones | H28: 7 | I28: 48736 | J28: 20 | K28: 272921.6 | L28: =Raw_Sales_Data3[[#This Row],[Quantity]]*Raw_Sales_Data3[[#This Row],[Unit Price]]*(Raw_Sales_Data3[[#This Row],[Discount %]]/100) -> 68230.4 | M28: =IF(COUNTIF(Raw_Sales_Data3[Order ID],Raw_Sales_Data3[[#This Row],[Order ID]])>1,"Duplicate Order ID","Unique Order ID") -> Unique Order ID
A29: ORD10028 | B29: 46028 | C29: Pooja Mehta | D29: South | E29: Rahul | F29: Furniture | G29: Chair | H29: 6 | I29: 35541 | J29: 0 | K29: 213246 | L29: =Raw_Sales_Data3[[#This Row],[Quantity]]*Raw_Sales_Data3[[#This Row],[Unit Price]]*(Raw_Sales_Data3[[#This Row],[Discount %]]/100) -> 0 | M29: =IF(COUNTIF(Raw_Sales_Data3[Order ID],Raw_Sales_Data3[[#This Row],[Order ID]])>1,"Duplicate Order ID","Unique Order ID") -> Duplicate Order ID
A30: ORD10028 | B30: 46098 | C30: Pooja Mehta | D30: South | E30: Kiran | F30: Electronics | G30: Laptop | H30: 12 | I30: 9109 | J30: 0 | K30: 109308 | L30: =Raw_Sales_Data3[[#This Row],[Quantity]]*Raw_Sales_Data3[[#This Row],[Unit Price]]*(Raw_Sales_Data3[[#This Row],[Discount %]]/100) -> 0 | M30: =IF(COUNTIF(Raw_Sales_Data3[Order ID],Raw_Sales_Data3[[#This Row],[Order ID]])>1,"Duplicate Order ID","Unique Order ID") -> Duplicate Order ID
A31: ORD10030 | B31: 46042 | C31: Vikram Joshi | D31: West | E31: Rahul | F31: Office Supplies | G31: Whiteboard | H31: 13 | I31: 55952 | J31: 10 | K31: 654638.4 | L31: =Raw_Sales_Data3[[#This Row],[Quantity]]*Raw_Sales_Data3[[#This Row],[Unit Price]]*(Raw_Sales_Data3[[#This Row],[Discount %]]/100) -> 72737.6 | M31: =IF(COUNTIF(Raw_Sales_Data3[Order ID],Raw_Sales_Data3[[#This Row],[Order ID]])>1,"Duplicate Order ID","Unique Order ID") -> Unique Order ID
A32: ORD10031 | B32: 46107 | C32: Ritu Sharma | D32: North | E32: Sneha | F32: Furniture | G32: Cabinet | H32: 13 | I32: 47117 | J32: 5 | K32: 581894.95 | L32: =Raw_Sales_Data3[[#This Row],[Quantity]]*Raw_Sales_Data3[[#This Row],[Unit Price]]*(Raw_Sales_Data3[[#This Row],[Discount %]]/100) -> 30626.05 | M32: =IF(COUNTIF(Raw_Sales_Data3[Order ID],Raw_Sales_Data3[[#This Row],[Order ID]])>1,"Duplicate Order ID","Unique Order ID") -> Unique Order ID | R32: s
A33: ORD10032 | B33: 46028 | C33: Aditya Joshi | D33: South | E33: Ajay | F33: Furniture | G33: Dining Table | H33: 3 | I33: 1242 | J33: 0 | K33: 3726 | L33: =Raw_Sales_Data3[[#This Row],[Quantity]]*Raw_Sales_Data3[[#This Row],[Unit Price]]*(Raw_Sales_Data3[[#This Row],[Discount %]]/100) -> 0 | M33: =IF(COUNTIF(Raw_Sales_Data3[Order ID],Raw_Sales_Data3[[#This Row],[Order ID]])>1,"Duplicate Order ID","Unique Order ID") -> Unique Order ID
A34: ORD10033 | B34: 46108 | C34: Sonia Kapoor | D34: South | E34: Ajay | F34: Office Supplies | G34: Stapler | H34: 10 | I34: 59608 | J34: 0 | K34: 596080 | L34: =Raw_Sales_Data3[[#This Row],[Quantity]]*Raw_Sales_Data3[[#This Row],[Unit Price]]*(Raw_Sales_Data3[[#This Row],[Discount %]]/100) -> 0 | M34: =IF(COUNTIF(Raw_Sales_Data3[Order ID],Raw_Sales_Data3[[#This Row],[Order ID]])>1,"Duplicate Order ID","Unique Order ID") -> Unique Order ID
A35: ORD10034 | B35: 46057 | C35: Nisha Jain | D35: North | E35: Sneha | F35: Office Supplies | G35: Printer | H35: 12 | I35: 2607 | J35: 15 | K35: 26591.4 | L35: =Raw_Sales_Data3[[#This Row],[Quantity]]*Raw_Sales_Data3[[#This Row],[Unit Price]]*(Raw_Sales_Data3[[#This Row],[Discount %]]/100) -> 4692.6 | M35: =IF(COUNTIF(Raw_Sales_Data3[Order ID],Raw_Sales_Data3[[#This Row],[Order ID]])>1,"Duplicate Order ID","Unique Order ID") -> Unique Order ID
A36: ORD10035 | B36: 46038 | C36: Neha Gupta | D36: North | E36: Rohit | F36: Electronics | G36: Mouse | H36: 10 | I36: 54562 | J36: 5 | K36: 518339 | L36: =Raw_Sales_Data3[[#This Row],[Quantity]]*Raw_Sales_Data3[[#This Row],[Unit Price]]*(Raw_Sales_Data3[[#This Row],[Discount %]]/100) -> 27281 | M36: =IF(COUNTIF(Raw_Sales_Data3[Order ID],Raw_Sales_Data3[[#This Row],[Order ID]])>1,"Duplicate Order ID","Unique Order ID") -> Unique Order ID
A37: ORD10036 | B37: 46067 | C37: Anjali Verma | D37: South | E37: Rahul | F37: Electronics | G37: Laptop | H37: 13 | I37: 52153 | J37: 0 | K37: 677989 | L37: =Raw_Sales_Data3[[#This Row],[Quantity]]*Raw_Sales_Data3[[#This Row],[Unit Price]]*(Raw_Sales_Data3[[#This Row],[Discount %]]/100) -> 0 | M37: =IF(COUNTIF(Raw_Sales_Data3[Order ID],Raw_Sales_Data3[[#This Row],[Order ID]])>1,"Duplicate Order ID","Unique Order ID") -> Unique Order ID
A38: ORD10037 | B38: 46063 | C38: Harsh Patel | D38: West | E38: Ajay | F38: Electronics | G38: Tablet | H38: 15 | I38: 25324 | J38: 5 | K38: 360867 | L38: =Raw_Sales_Data3[[#This Row],[Quantity]]*Raw_Sales_Data3[[#This Row],[Unit Price]]*(Raw_Sales_Data3[[#This Row],[Discount %]]/100) -> 18993 | M38: =IF(COUNTIF(Raw_Sales_Data3[Order ID],Raw_Sales_Data3[[#This Row],[Order ID]])>1,"Duplicate Order ID","Unique Order ID") -> Unique Order ID
A39: ORD10038 | B39: 46069 | C39: Sonia Kapoor | D39: West | E39: Kiran | F39: Furniture | G39: Dining Table | H39: 13 | I39: 19712 | J39: 10 | K39: 230630.4 | L39: =Raw_Sales_Data3[[#This Row],[Quantity]]*Raw_Sales_Data3[[#This Row],[Unit Price]]*(Raw_Sales_Data3[[#This Row],[Discount %]]/100) -> 25625.6 | M39: =IF(COUNTIF(Raw_Sales_Data3[Order ID],Raw_Sales_Data3[[#This Row],[Order ID]])>1,"Duplicate Order ID","Unique Order ID") -> Unique Order ID
A40: ORD10039 | B40: 46032 | C40: Amit Sharma | D40: East | E40: Kiran | F40: Office Supplies | G40: Printer | H40: 2 | I40: 44490 | J40: 20 | K40: 71184 | L40: =Raw_Sales_Data3[[#This Row],[Quantity]]*Raw_Sales_Data3[[#This Row],[Unit Price]]*(Raw_Sales_Data3[[#This Row],[Discount %]]/100) -> 17796 | M40: =IF(COUNTIF(Raw_Sales_Data3[Order ID],Raw_Sales_Data3[[#This Row],[Order ID]])>1,"Duplicate Order ID","Unique Order ID") -> Unique Order ID
A41: ORD10040 | B41: 46088 | C41: Priya Patel | D41: West | E41: Ajay | F41: Furniture | G41: Desk | H41: =K41/(I41*(1-J41/100)) -> 8 | I41: 31116 | J41: 20 | K41: 199142.4 | L41: =Raw_Sales_Data3[[#This Row],[Quantity]]*Raw_Sales_Data3[[#This Row],[Unit Price]]*(Raw_Sales_Data3[[#This Row],[Discount %]]/100) -> 49785.6 | M41: =IF(COUNTIF(Raw_Sales_Data3[Order ID],Raw_Sales_Data3[[#This Row],[Order ID]])>1,"Duplicate Order ID","Unique Order ID") -> Unique Order ID
A42: ORD10041 | C42: Komal Gupta | D42: North | E42: Sneha | F42: Furniture | G42: Chair | H42: 5 | I42: 4170 | J42: 5 | K42: 19807.5 | L42: =Raw_Sales_Data3[[#This Row],[Quantity]]*Raw_Sales_Data3[[#This Row],[Unit Price]]*(Raw_Sales_Data3[[#This Row],[Discount %]]/100) -> 1042.5 | M42: =IF(COUNTIF(Raw_Sales_Data3[Order ID],Raw_Sales_Data3[[#This Row],[Order ID]])>1,"Duplicate Order ID","Unique Order ID") -> Unique Order ID
A43: ORD10042 | B43: 46061 | C43: Neha Gupta | D43: South | E43: Sneha | F43: Furniture | G43: Bed | H43: 13 | I43: 57192 | J43: 15 | K43: 631971.6 | L43: =Raw_Sales_Data3[[#This Row],[Quantity]]*Raw_Sales_Data3[[#This Row],[Unit Price]]*(Raw_Sales_Data3[[#This Row],[Discount %]]/100) -> 111524.4 | M43: =IF(COUNTIF(Raw_Sales_Data3[Order ID],Raw_Sales_Data3[[#This Row],[Order ID]])>1,"Duplicate Order ID","Unique Order ID") -> Unique Order ID
A44: ORD10043 | B44: 46071 | C44: Ritu Sharma | D44: West | E44: Ajay | F44: Office Supplies | G44: File Cabinet | H44: 13 | I44: 18484 | J44: 10 | K44: 216262.8 | L44: =Raw_Sales_Data3[[#This Row],[Quantity]]*Raw_Sales_Data3[[#This Row],[Unit Price]]*(Raw_Sales_Data3[[#This Row],[Discount %]]/100) -> 24029.2 | M44: =IF(COUNTIF(Raw_Sales_Data3[Order ID],Raw_Sales_Data3[[#This Row],[Order ID]])>1,"Duplicate Order ID","Unique Order ID") -> Unique Order ID
A45: ORD10044 | B45: 46087 | C45: Priya Patel | D45: South | E45: Ajay | F45: Furniture | G45: Tablet | H45: 15 | I45: 26578 | J45: 10 | K45: 358803 | L45: =Raw_Sales_Data3[[#This Row],[Quantity]]*Raw_Sales_Data3[[#This Row],[Unit Price]]*(Raw_Sales_Data3[[#This Row],[Discount %]]/100) -> 39867 | M45: =IF(COUNTIF(Raw_Sales_Data3[Order ID],Raw_Sales_Data3[[#This Row],[Order ID]])>1,"Duplicate Order ID","Unique Order ID") -> Unique Order ID
A46: ORD10045 | B46: 46066 | C46: Sonia Kapoor | D46: West | E46: Ajay | F46: Office Supplies | G46: Whiteboard | H46: 4 | I46: 11215 | J46: 0 | K46: 44860 | L46: =Raw_Sales_Data3[[#This Row],[Quantity]]*Raw_Sales_Data3[[#This Row],[Unit Price]]*(Raw_Sales_Data3[[#This Row],[Discount %]]/100) -> 0 | M46: =IF(COUNTIF(Raw_Sales_Data3[Order ID],Raw_Sales_Data3[[#This Row],[Order ID]])>1,"Duplicate Order ID","Unique Order ID") -> Unique Order ID
...

Sheet cleaning_log
A1: Issue | B1: Count | C1: Action Taken
A2: Duplicate Order IDs | B2: 28 | C2: Investigated and retained (not identical rows)
A3: Missing Order Dates | B3: 31 | C3: Left blanks
A4: Blank Discount | B4: 367 | C4: Replaced with 0%
A5: Blank Unit Price | B5: 29 | C5: Calculated using sales/quantity
A6: Extra Spaces | B6: - | C6: Removed using trim()
A7: Region inconsistencies | B7: - | C7: Standardized
A8: Blank Quantity | B8: 29 | C8: Calculated using sales/(unit price*(1-discount%/100))

Sheet Analysis
A1: total sales | C1: total orders | E1: total customers | H1: total sales by each region | K1: best region | M1: worst region | O1: total quantity sold | R1: average order value | U1: average discount %
A2: =SUM(clean_data!K:K) -> 2.1714819e+08 | C2: =COUNTA(clean_data!A2:A1001) -> 1000 | E2: =COUNTA(_xlfn.UNIQUE(clean_data!C2:C1001)) -> 20 | H2: East | I2: =SUMIF(clean_data!D:D,"East",clean_data!K:K) -> 41812570 | K2: =_xlfn.XLOOKUP(MAX(I2:I5),I2:I5,H2:H5) -> South | M2: =_xlfn.XLOOKUP(MIN(I2:I5),I2:I5,H2:H5) -> East | O2: =SUM(clean_data!H:H) -> 8035 | R2: =A2/C2 -> 217148.19 | U2: =AVERAGE(clean_data!J:J) -> 8.025
H3: West | I3: =SUMIF(clean_data!D:D,"West",clean_data!K:K) -> 60196984
H4: South | I4: =SUMIF(clean_data!D:D,"South",clean_data!K:K) -> 61336096
H5: North | I5: =SUMIF(clean_data!D:D,"North",clean_data!K:K) -> 53802544
A8: total sales by each category | D8: Best Category | F8: total sales by each salesperson | I8: Best Salesperson | K8: Lowest Salesperson
A9: Furniture | B9: =SUMIFS(clean_data!K:K,clean_data!F:F,"Furniture") -> 64976356 | D9: =_xlfn.XLOOKUP(MAX(B9:B11),B9:B11,A9:A11) -> Office Supplies | F9: Ajay | G9: =SUMIFS(clean_data!K:K,clean_data!E:E,"Ajay") -> 43404867 | I9: =_xlfn.XLOOKUP(MAX(G9:G13),G9:G13,F9:F13) -> Kiran | K9: =_xlfn.XLOOKUP(MIN(G9:G13),G9:G13,F9:F13) -> Sneha
A10: Electronics | B10: =SUMIFS(clean_data!K:K,clean_data!F:F,"Electronics") -> 72648810 | F10: Kiran | G10: =SUMIFS(clean_data!K:K,clean_data!E:E,"Kiran") -> 46363642
A11: Office Supplies | B11: =SUMIFS(clean_data!K:K,clean_data!F:F,"Office Supplies") -> 79523028 | D11: Worst Category | F11: Rahul | G11: =SUMIFS(clean_data!K:K,clean_data!E:E,"Rahul") -> 40803061
D12: =_xlfn.XLOOKUP(MIN(B9:B11),B9:B11,A9:A11) -> Furniture | F12: Rohit | G12: =SUMIFS(clean_data!K:K,clean_data!E:E,"Rohit") -> 45903246
F13: Sneha | G13: =SUMIFS(clean_data!K:K,clean_data!E:E,"Sneha") -> 40673377
P15: KPI'S
P17: Total Sales
P18: Orders
P19: Customers
P20: Quantity
P21: Average Order Value
P22: Average Discount %
K25: BUSINESS INSIGHTS
K27: ✓ South region generated the highest sales (₹61.34M).
K29: ✓ Office Supplies is the best-performing category (₹79.52M).
K31: ✓ Kiran is the top salesperson (₹46.63M).
K33: ✓ Printer is the highest-selling product (₹18.56M).
K35: ✓ Average Order Value is ₹2.17L, indicating high-value transactions.
K37: Average discount remains below 10%.

Sheet pivot_tables
A1: sales by region | E1: sales by category | I1: sales by salesperson | M1: sales trend
A2: Row Labels | B2: Sum of Sales | E2: Row Labels | F2: Sum of Sales | I2: Row Labels | J2: Sum of Sales | M2: Row Labels | N2: Sum of Sales
A3: East | B3: 41812570 | E3: Electronics | F3: 72648810 | I3: Sneha | J3: 40673377 | M3: <01-01-2026 | N3: 5681560.2
A4: North | B4: 53802544 | E4: Furniture | F4: 64976356 | I4: Rahul | J4: 40803061 | M4: Jan | N4: 76208567
A5: South | B5: 61336096 | E5: Office Supplies | F5: 79523028 | I5: Ajay | J5: 43404867 | M5: Feb | N5: 61830982
A6: West | B6: 60196984 | E6: Grand Total | F6: 2.1714819e+08 | I6: Rohit | J6: 45903246 | M6: Mar | N6: 73427085
A7: Grand Total | B7: 2.1714819e+08 | I7: Kiran | J7: 46363642 | M7: Grand Total | N7: 2.1714819e+08
I8: Grand Total | J8: 2.1714819e+08
A12: sales by product | E12: top product | I12: top 5 customers by purchase
A13: Row Labels | B13: Sum of Sales | E13: Row Labels | F13: Sum of Sales | I13: Row Labels | J13: Sum of Sales
A14: Bed | B14: 7471714.3 | E14: Printer | F14: 16557844 | I14: Meera Nair | J14: 12054375
A15: Bookshelf | B15: 7653711 | I15: Anjali Verma | J15: 12189804
A16: Cabinet | B16: 11814435 | I16: Nisha Jain | J16: 13078638
A17: Camera | B17: 6583213.4 | I17: Neha Gupta | J17: 13893137
A18: Chair | B18: 7375328.8 | I18: Ritu Sharma | J18: 14499788
A19: Coffee Table | B19: 6557613 | E19: bottom product | I19: Grand Total | J19: 65715743
A20: Desk | B20: 7620481.5 | E20: Row Labels | F20: Sum of Sales
A21: Dining Table | B21: 6737013.3 | E21: Speaker | F21: 4953743
A22: File Cabinet | B22: 15237199
A23: Headphones | B23: 6044088.1 | I23: top customer
A24: Keyboard | B24: 6360838.2 | I24: Row Labels | J24: Sum of Sales
A25: Laptop | B25: 9876692.5 | I25: Ritu Sharma | J25: 14499788
A26: Monitor | B26: 5602371.1 | E26: top 5 Product
A27: Mouse | B27: 9789306.1 | E27: Row Labels | F27: Sum of Sales
A28: Printer | B28: 16557844 | E28: Whiteboard | F28: 12711507
A29: Projector | B29: 9668031.3 | E29: Scanner | F29: 12862118
A30: Scanner | B30: 12862118 | E30: Stapler | F30: 13775542
A31: Smartphone | B31: 6132165.2 | E31: File Cabinet | F31: 15237199
A32: Sofa | B32: 9156805.8 | E32: Printer | F32: 16557844
A33: Speaker | B33: 4953743 | E33: Grand Total | F33: 71144211
A34: Stapler | B34: 13775542
A35: Tablet | B35: 8202795.4
A36: Tv | B36: 8403636.2
A37: Whiteboard | B37: 12711507
A38: Grand Total | B38: 217148194

Sheet Dashboard
